Workbook

Sheet Tổng quan
A1: Phụ kiện từng súng PUBG Mobile / 和平精英: tra cứu cho 38 mã súng chưa có quy tắc
A2: Lập ngày 14/10/2026. Gồm đối chiếu 30 súng trong bảng của bạn với dữ liệu chính thức của Tencent. Chưa áp dụng vào app.
A4: Số liệu (tính bằng công thức từ các sheet bên cạnh)
A5: Tổng số mã súng trong app | B5: 68 | C5: Danh sách WEAPONS của app
A6: Mã đã có quy tắc (bảng của bạn) | B6: =COUNTA('Đối chiếu 30 súng trong bảng'!A5:A34) -> 30
A7: Mã chưa có quy tắc (tra cứu trong file này) | B7: =COUNTA('38 súng chưa có quy tắc'!B5:B42) -> 38
A8: độ tin cậy Cao | B8: =COUNTIF('38 súng chưa có quy tắc'!E5:E42,"Cao") -> 5 | C8: Dữ liệu chính thức 和平精英 (kiểm chứng chéo khi có)
A9: độ tin cậy Trung bình | B9: =COUNTIF('38 súng chưa có quy tắc'!E5:E42,"Trung bình") -> 6 | C9: Nguồn thứ cấp bản toàn cầu hoặc có mâu thuẫn
A10: độ tin cậy Thấp | B10: =COUNTIF('38 súng chưa có quy tắc'!E5:E42,"Thấp") -> 2 | C10: Bài trước phát hành hoặc bản PC
A11: Chưa tìm thấy nguồn | B11: =COUNTIF('38 súng chưa có quy tắc'!E5:E42,"Chưa tìm thấy") -> 22 | C11: Cần nguồn khác hoặc kiểm tra trong game
A12: Không phải súng | B12: =COUNTIF('38 súng chưa có quy tắc'!E5:E42,"Không áp dụng") -> 3 | C12: Empty, SHIELD, MORTAR
A13: Mã có đề xuất áp dụng được ngay | B13: =COUNTIF('38 súng chưa có quy tắc'!O5:O42,"Áp dụng được") -> 5 | C13: Dữ liệu chính thức, kiểm chứng chéo
A14: Mã có đề xuất nhưng cần bạn xác nhận | B14: =COUNTIF('38 súng chưa có quy tắc'!O5:O42,"Cần xác nhận") -> 6 | C14: Một nguồn hoặc nguồn mâu thuẫn
A15: Ô khác biệt giữa bảng của bạn và dữ liệu chính thức: nòng | B15: =COUNTIF('Đối chiếu 30 súng trong bảng'!L5:L34,"KHÁC") -> 2 | C15: Sheet "Đối chiếu 30 súng trong bảng", cột L
A16: tay cầm | B16: =COUNTIF('Đối chiếu 30 súng trong bảng'!M5:M34,"KHÁC") -> 13 | C16: cột M
A17: báng | B17: =COUNTIF('Đối chiếu 30 súng trong bảng'!N5:N34,"KHÁC") -> 2 | C17: cột N
A18: ống ngắm | B18: =COUNTIF('Đối chiếu 30 súng trong bảng'!O5:O34,"KHÁC") -> 3 | C18: cột O
A20: Phát hiện chính
A21: Có dữ liệu chính thức của Tencent cho 45 vũ khí 和平精英, trong đó 33 súng khớp mã của app (30 trong bảng của bạn: 27; cộng 6 súng chưa có quy tắc: CrossBow, MG3, M249, DBS, Bison, Win94).
A22: Trong 38 mã chưa có quy tắc: 6 có dữ liệu chính thức (5 mức Cao; M249 mức Trung bình vì các phiên bản game mâu thuẫn), 4 có nguồn thứ cấp (Mosin, M1014, MP5K, P90), AMR (nguồn thứ cấp: chỉ một khe ống ngắm), M417 và JS9 chỉ có rất ít thông tin, 3 không phải súng, 22 chưa tìm được nguồn đáng tin.
A23: Bảng của bạn có khác biệt với dữ liệu chính thức ở nhiều súng (xem sheet "Đối chiếu 30 súng trong bảng", ô đỏ): ví dụ Groza chỉ gắn nòng giảm thanh; Mk47 và M16A4 gắn được báng chiến thuật; Tommy Gun gắn được tay cầm đứng; Vector không có tay cầm tam giác/ngón cái; SLR và Mk14 không có tay cầm; VSS không có nòng và không lắp ống ngắm; hầu hết súng có tay cầm đều gắn thêm được Laser.
A24: Dữ liệu chính thức không có: ACE32, FAMAS, MK12 (đối chiếu FAMAS và MK12 bằng AppMedia), và hầu hết súng mới thêm gần đây (AMR, M417, JS9, MP7, ARX, MG36, AA12, SPAS-12, AS50, M200, SVD, PKM...). Với các súng này không có nguồn đáng tin nên mình KHÔNG đề xuất quy tắc (để app không hạn chế).
A26: Các sheet
A27: 38 súng chưa có quy tắc | C27: 38 mã chưa có quy tắc: kết quả tra cứu và đề xuất theo tên enum của app
A28: Đối chiếu 30 súng trong bảng | C28: 30 súng trong bảng của bạn so với dữ liệu chính thức (có công thức Khớp/KHÁC)
A29: Chính thức 和平精英 (45 súng) | C29: Dữ liệu chính thức Tencent, nguyên văn tiếng Trung và đã ánh xạ sang app
A30: Phụ kiện → súng (chính thức) | C30: Từng phụ kiện chính thức và danh sách súng áp dụng
A31: AppMedia (toàn cầu 2022) | C31: Bảng AppMedia bản toàn cầu
A32: Nguồn | C32: Nguồn, ngày, độ tin cậy, hạn chế
A33: Ghi chú và giả định | C33: Giả định và cách ánh xạ

Sheet 38 súng chưa có quy tắc
A1: 38 mã súng của app mà bảng của bạn chưa có: kết quả tra cứu
A2: Cột "Đề xuất" dùng đúng tên của app (COMPENSATOR, VERTICAL, GENERAL...). "—" = không lắp được; ô trống = chưa có đề xuất. Ống ngắm tối đa tính theo mục ống ngắm của app (X63=6x, X84=8x...).
A4: STT | B4: Mã (app) | C4: Tên súng (nhận diện) | D4: Loại | E4: Độ tin cậy | F4: Đầu nòng | G4: Tay cầm | H4: Báng | I4: Ống ngắm | J4: Băng đạn / khác | K4: Đề xuất: đầu nòng | L4: Đề xuất: tay cầm | M4: Đề xuất: báng | N4: Đề xuất: ống ngắm tối đa | O4: Trạng thái đề xuất | P4: Nguồn | Q4: Ghi chú
A5: 1 | B5: Empty | C5: (Không súng / tay không) | D5: Đặc biệt | E5: Không áp dụng | F5: — | G5: — | H5: — | I5: — | J5: — | O5: Không áp dụng | P5: — | Q5: Không phải súng. App đã xử lý là súng luôn bằng 0.
A6: 2 | B6: CrossBow | C6: Nỏ (Crossbow) | D6: Khác | E6: Cao | F6: — | G6: Túi tên (Quiver) | H6: — | I6: 6x | J6: Băng đạn: — | K6: — | L6: — | M6: — | N6: 6 | O6: Áp dụng được | P6: Chính thức 和平精英 (Tencent); AppMedia | Q6: Khớp AppMedia (Red Dot, Holo, 2–6x; chỉ có Túi tên). Túi tên không có trong danh sách tay cầm của app.
A7: 3 | B7: Mosin | C7: Mosin-Nagant | D7: Súng bắn tỉa (SR) | E7: Trung bình | F7: Hãm giật, Ẩn tia lửa, Giảm thanh (loại SR) | G7: — | H7: Ốp má (Cheek Pad), Vỏ đạn (Shell Holder): không có trong app | I7: RD, Holo, Canted, 2–8x | J7: Không băng đạn | K7: COMPENSATOR, FLASH_HIDER, SUPPRESSOR | L7: — | M7: — | N7: 8 | O7: Cần xác nhận | P7: AppMedia 武器一覧 (PUBG Mobile toàn cầu, 27/05/2022) | Q7: Chỉ AppMedia (bản toàn cầu); súng không có trong dữ liệu chính thức 和平精英. Một nguồn khác (BGMI, chưa kiểm chứng) nói Mosin bị gỡ khỏi bản đồ năm 2026.
A8: 4 | B8: MG3 | C8: MG3 | D8: Súng máy (LMG) | E8: Cao | F8: — | G8: — | H8: — | I8: 6x | J8: Băng đạn: — | K8: — | L8: — | M8: — | N8: 6 | O8: Áp dụng được | P8: Chính thức 和平精英 (Tencent); AppMedia | Q8: Khớp AppMedia và bài 18183 (MG3 không phụ thuộc phụ kiện). Chỉ lắp ống ngắm.
A9: 5 | B9: M249 | C9: M249 | D9: Súng máy (LMG) | E9: Trung bình | F9: — | G9: — | H9: — | I9: 6x + ống ngắm bên | J9: Băng đạn: — | K9: — | L9: — | M9: — | N9: 6 | O9: Cần xác nhận | P9: Chính thức 和平精英 (Tencent); AppMedia (khác) | Q9: MÂU THUẪN giữa các phiên bản: dữ liệu chính thức 和平精英 chỉ cho ống ngắm; AppMedia và mobilematters.gg (bản toàn cầu) ghi M249 lắp được Báng chiến thuật. Bạn chơi bản nào thì theo bản đó; đề xuất theo bản chính thức 和平精英.
A10: 6 | B10: PKM | C10: PKM (suy từ mã) | D10: Súng máy (LMG) | E10: Chưa tìm thấy | F10: — | G10: — | H10: — | I10: — | J10: — | O10: Không đủ dữ liệu | P10: — | Q10: Không tìm thấy nguồn nào. Bản toàn cầu thêm RPD (2026), không rõ PKM.
A11: 7 | B11: ASM | C11: ASM Abakan = AN-94 (theo IMFDB) | D11: Súng trường tấn công (AR) | E11: Chưa tìm thấy | F11: — | G11: — | H11: — | I11: — | J11: — | O11: Không đủ dữ liệu | P11: — | Q11: Chỉ có một dòng IMFDB nói "ASM Abakan" được thêm vào PUBG Mobile. Có thể trùng mã ABAKAN.
A12: 8 | B12: DBS | C12: DBS | D12: Shotgun (SG) | E12: Cao | F12: — | G12: — | H12: — | I12: 6x + ống ngắm bên | J12: Băng đạn: — | K12: — | L12: — | M12: — | N12: 6 | O12: Áp dụng được | P12: Chính thức 和平精英 (Tencent); AppMedia | Q12: Khớp AppMedia (RD, Holo, Canted, 2–6x; không phụ kiện khác).
A13: 9 | B13: M1014 | C13: M1014 | D13: Shotgun (SG) | E13: Trung bình | F13: — | G13: — | H13: Vỏ đạn (Shell Holder): không có trong app | I13: không lắp ống ngắm | J13: Choke, Duckbill, Shell Holder | K13: — | L13: — | M13: — | N13: 0 | O13: Cần xác nhận | P13: AppMedia 武器一覧 (PUBG Mobile toàn cầu, 27/05/2022) | Q13: Chỉ AppMedia (bản toàn cầu). Choke/Duckbill không có trong danh sách nòng của app.
A14: 10 | B14: MP5K | C14: MP5K | D14: Súng tiểu liên (SMG) | E14: Trung bình | F14: Hãm giật, Ẩn tia lửa, Giảm thanh | G14: Đứng, Nhẹ, Half (AppMedia); xem ghi chú | H14: Báng chiến thuật | I14: RD, Holo, Canted, 2–6x | J14: Băng đạn QD/LM/LQD; Laser | K14: COMPENSATOR, FLASH_HIDER, SUPPRESSOR | L14: HALF, LASER, LIGHT, VERTICAL | M14: GENERAL | N14: 6 | O14: Cần xác nhận | P14: AppMedia 武器一覧 (PUBG Mobile toàn cầu, 27/05/2022); mobilematters.gg | Q14: Nguồn mâu thuẫn về tay cầm: AppMedia = Đứng/Nhẹ/Half (+Laser); mobilematters.gg dựng MP5K với Tay cầm tam giác; Sportskeeda ghi cả Ngón cái. Đề xuất theo AppMedia (hẹp hơn, an toàn hơn).
A15: 11 | B15: Bison | C15: PP-19 Bizon | D15: Súng tiểu liên (SMG) | E15: Cao | F15: Hãm giật, Ẩn tia lửa, Giảm thanh | G15: — | H15: — | I15: 6x + ống ngắm bên | J15: Băng đạn: — | K15: COMPENSATOR, FLASH_HIDER, SUPPRESSOR | L15: — | M15: — | N15: 6 | O15: Áp dụng được | P15: Chính thức 和平精英 (Tencent); AppMedia | Q15: Khớp AppMedia (Comp/FH/Supp, RD/Holo/2–6x, không tay cầm, không báng).
A16: 12 | B16: P90 | C16: P90 | D16: Súng tiểu liên (SMG) | E16: Trung bình | F16: Hãm giật, Ẩn tia lửa, Giảm thanh | G16: Laser (đặt ở khe tay cầm) | H16: — | I16: RD, Holo, 2–6x | J16: Không băng đạn | K16: COMPENSATOR, FLASH_HIDER, SUPPRESSOR | L16: LASER | M16: — | N16: 6 | O16: Cần xác nhận | P16: AppMedia 武器一覧 (PUBG Mobile toàn cầu, 27/05/2022); mobilematters.gg | Q16: Khớp giữa AppMedia (Laser) và mobilematters.gg (Compensator + Red Dot + Laser làm tay cầm).
A17: 13 | B17: Win94 | C17: Win94 | D17: Súng bắn tỉa (SR) | E17: Cao | F17: — | G17: — | H17: Túi đạn (Bullet Loops) | I17: không lắp được ống ngắm | J17: Băng đạn: — | K17: — | L17: — | M17: — | N17: 0 | O17: Áp dụng được | P17: Chính thức 和平精英 (Tencent); AppMedia | Q17: "Không thể lắp ống ngắm". Báng duy nhất là Túi đạn (Bullet Loops), không có trong danh sách báng của app. Đề xuất ống ngắm tối đa 0 (chỉ bắn hông).
A18: 14 | B18: AMR | C18: AMR (Lynx AMR) | D18: Súng bắn tỉa (SR) | E18: Trung bình | F18: — | G18: — | H18: — | I18: Đến 8x (khuyên 8x, có thể 4x/6x) | J18: Chỉ có MỘT khe phụ kiện: ống ngắm | K18: — | L18: — | M18: — | N18: 8 | O18: Cần xác nhận | P18: mobilematters.gg (AMR loadout); game.xiaomi.com (AMR "chỉ cần một ống ngắm là đủ") | Q18: Hai nguồn cùng nói AMR chỉ có khe ống ngắm; mobilematters không nêu ngày bài. Chưa thấy nguồn chính thức.
A19: 15 | B19: ACVAL | C19: ACVAL (chưa nhận diện chắc) | D19: Chưa rõ | E19: Chưa tìm thấy | F19: — | G19: — | H19: — | I19: — | J19: — | O19: Không đủ dữ liệu | P19: — | Q19: Không tìm thấy nguồn nào.
A20: 16 | B20: Bow | C20: Cung (Bow) | D20: Cung | E20: Chưa tìm thấy | F20: — | G20: — | H20: — | I20: — | J20: — | O20: Không đủ dữ liệu | P20: — | Q20: Không tìm thấy nguồn. Suy luận: cung thường không có khe phụ kiện (chưa xác minh).
A21: 17 | B21: SPAS12 | C21: SPAS-12 | D21: Shotgun (SG) | E21: Chưa tìm thấy | F21: — | G21: — | H21: — | I21: — | J21: — | O21: Không đủ dữ liệu | P21: — | Q21: Không tìm thấy nguồn. Duckbill của bản PC chỉ ghi S1897 và S12K.
A22: 18 | B22: M417 | C22: M417 | D22: Súng trường xạ thủ (DMR) | E22: Thấp | F22: Chưa rõ | G22: Chưa rõ | H22: Chưa rõ | I22: Đến 8x | J22: Băng đạn mặc định 10 viên (cần băng mở rộng) | O22: Không đủ dữ liệu | P22: gurugamer.com (bài trước khi phát hành, 5.56mm, "hỗ trợ mọi ống ngắm đến 8x") | Q22: Chỉ có bài viết trước khi phát hành; Baidu Baike (chặn truy cập, không đọc được) được trích là nói M417 có đủ khe. Không đủ để đặt quy tắc; chỉ biết ống ngắm đến 8x.
A23: 19 | B23: HB | C23: HB (chưa nhận diện) | D23: Chưa rõ | E23: Chưa tìm thấy | F23: — | G23: — | H23: — | I23: — | J23: — | O23: Không đủ dữ liệu | P23: — | Q23: Không tìm thấy nguồn nào.
A24: 20 | B24: TacticsBow | C24: Cung chiến thuật (Tactical Bow) | D24: Cung | E24: Chưa tìm thấy | F24: — | G24: — | H24: — | I24: — | J24: — | O24: Không đủ dữ liệu | P24: — | Q24: Không tìm thấy nguồn. Suy luận như Cung (chưa xác minh).
A25: 21 | B25: MK20H | C25: Mk20-H (FN SSR theo IMFDB) | D25: Súng trường xạ thủ (DMR) | E25: Chưa tìm thấy | F25: — | G25: — | H25: — | I25: — | J25: — | O25: Không đủ dữ liệu | P25: — | Q25: Không tìm thấy dữ liệu phụ kiện.
A26: 22 | B26: M200 | C26: M200 (suy từ mã) | D26: Súng bắn tỉa (SR) | E26: Chưa tìm thấy | F26: — | G26: — | H26: — | I26: — | J26: — | O26: Không đủ dữ liệu | P26: — | Q26: Không tìm thấy nguồn (danh sách ốp má của bản PC không có M200).
A27: 23 | B27: SHIELD | C27: Khiên (Shield) | D27: Trang bị | E27: Không áp dụng | F27: — | G27: — | H27: — | I27: — | J27: — | O27: Không áp dụng | P27: — | Q27: Không phải súng, không có khe phụ kiện.
A28: 24 | B28: AA12G | C28: AA-12 (suy từ mã) | D28: Shotgun (SG) | E28: Chưa tìm thấy | F28: — | G28: — | H28: — | I28: — | J28: — | O28: Không đủ dữ liệu | P28: — | Q28: Không tìm thấy nguồn cho bản mobile (bản PC liệt kê O12).
A29: 25 | B29: AKS | C29: AKS-74U (suy từ mã) | D29: Súng trường tấn công (AR) | E29: Chưa tìm thấy | F29: — | G29: — | H29: — | I29: — | J29: — | O29: Không đủ dữ liệu | P29: — | Q29: Không tìm thấy nguồn.
A30: 26 | B30: FireCompositeBow | C30: Cung hỗn hợp lửa (Fire Composite Bow) | D30: Cung | E30: Chưa tìm thấy | F30: — | G30: — | H30: — | I30: — | J30: — | O30: Không đủ dữ liệu | P30: — | Q30: Không tìm thấy nguồn.
... A42: 38 | B42: ChiXiao | C42: 赤霄 (Xích Tiêu) | D42: Chưa rõ | E42: Chưa tìm thấy | F42: — | G42: — | H42: — | I42: — | J42: — | O42: Không đủ dữ liệu | P42: — | Q42: Không tìm thấy nguồn nào.

Sheet Đối chiếu 30 súng trong bảng
A1: Đối chiếu bảng của bạn (30 súng) với dữ liệu chính thức 和平精英 của Tencent
A2: Cột L–O là công thức: "Khớp" hoặc "KHÁC". Súng không có trong dữ liệu chính thức (ACE32, FAMAS, MK12) so với AppMedia nếu có. Đây chỉ là đề xuất, chưa áp dụng vào app.
A4: Mã (app) | B4: Tên | C4: Nòng (bảng hiện tại) | D4: Tay cầm (hiện tại) | E4: Báng (hiện tại) | F4: Ống ngắm ≤ (hiện tại) | G4: Nguồn đối chiếu | H4: Nòng (nguồn) | I4: Tay cầm (nguồn) | J4: Báng (nguồn) | K4: Ống ngắm ≤ (nguồn) | L4: Nòng? | M4: Tay cầm? | N4: Báng? | O4: Ống ngắm? | P4: Khác biệt cụ thể | Q4: Đề xuất
A5: M416 | B5: M416 | C5: COMPENSATOR, FLASH_HIDER, SUPPRESSOR | D5: HALF, HORIZONTAL, LIGHT, THUMB, VERTICAL | E5: GENERAL | F5: 6 | G5: Chính thức 和平精英 | H5: COMPENSATOR, FLASH_HIDER, SUPPRESSOR | I5: HALF, HORIZONTAL, LASER, LIGHT, THUMB, VERTICAL | J5: GENERAL | K5: 6 | L5: =IF($G5="Không có nguồn","—",IF(C5=H5,"Khớp","KHÁC")) -> Khớp | M5: =IF($G5="Không có nguồn","—",IF(D5=I5,"Khớp","KHÁC")) -> KHÁC | N5: =IF($G5="Không có nguồn","—",IF(E5=J5,"Khớp","KHÁC")) -> Khớp | O5: =IF($G5="Không có nguồn","—",IF(F5=K5,"Khớp","KHÁC")) -> Khớp | P5: Tay cầm: hiện tại HALF, HORIZONTAL, LIGHT, THUMB, VERTICAL, nguồn HALF, HORIZONTAL, LASER, LIGHT, THUMB, VERTICAL | Q5: Sửa theo nguồn: Tay cầm
A6: Scar | B6: SCAR-L | C6: COMPENSATOR, FLASH_HIDER, SUPPRESSOR | D6: HALF, HORIZONTAL, LIGHT, THUMB, VERTICAL | E6: — | F6: 6 | G6: Chính thức 和平精英 | H6: COMPENSATOR, FLASH_HIDER, SUPPRESSOR | I6: HALF, HORIZONTAL, LASER, LIGHT, THUMB, VERTICAL | J6: — | K6: 6 | L6: =IF($G6="Không có nguồn","—",IF(C6=H6,"Khớp","KHÁC")) -> Khớp | M6: =IF($G6="Không có nguồn","—",IF(D6=I6,"Khớp","KHÁC")) -> KHÁC | N6: =IF($G6="Không có nguồn","—",IF(E6=J6,"Khớp","KHÁC")) -> Khớp | O6: =IF($G6="Không có nguồn","—",IF(F6=K6,"Khớp","KHÁC")) -> Khớp | P6: Tay cầm: hiện tại HALF, HORIZONTAL, LIGHT, THUMB, VERTICAL, nguồn HALF, HORIZONTAL, LASER, LIGHT, THUMB, VERTICAL | Q6: Sửa theo nguồn: Tay cầm
A7: G36C | B7: G36C | C7: COMPENSATOR, FLASH_HIDER, SUPPRESSOR | D7: HALF, HORIZONTAL, LIGHT, THUMB, VERTICAL | E7: — | F7: 6 | G7: Chính thức 和平精英 | H7: COMPENSATOR, FLASH_HIDER, SUPPRESSOR | I7: HALF, HORIZONTAL, LASER, LIGHT, THUMB, VERTICAL | J7: — | K7: 6 | L7: =IF($G7="Không có nguồn","—",IF(C7=H7,"Khớp","KHÁC")) -> Khớp | M7: =IF($G7="Không có nguồn","—",IF(D7=I7,"Khớp","KHÁC")) -> KHÁC | N7: =IF($G7="Không có nguồn","—",IF(E7=J7,"Khớp","KHÁC")) -> Khớp | O7: =IF($G7="Không có nguồn","—",IF(F7=K7,"Khớp","KHÁC")) -> Khớp | P7: Tay cầm: hiện tại HALF, HORIZONTAL, LIGHT, THUMB, VERTICAL, nguồn HALF, HORIZONTAL, LASER, LIGHT, THUMB, VERTICAL | Q7: Sửa theo nguồn: Tay cầm
A8: QBZ | B8: QBZ | C8: COMPENSATOR, FLASH_HIDER, SUPPRESSOR | D8: HALF, HORIZONTAL, LIGHT, THUMB, VERTICAL | E8: — | F8: 6 | G8: Chính thức 和平精英 | H8: COMPENSATOR, FLASH_HIDER, SUPPRESSOR | I8: HALF, HORIZONTAL, LASER, LIGHT, THUMB, VERTICAL | J8: — | K8: 6 | L8: =IF($G8="Không có nguồn","—",IF(C8=H8,"Khớp","KHÁC")) -> Khớp | M8: =IF($G8="Không có nguồn","—",IF(D8=I8,"Khớp","KHÁC")) -> KHÁC | N8: =IF($G8="Không có nguồn","—",IF(E8=J8,"Khớp","KHÁC")) -> Khớp | O8: =IF($G8="Không có nguồn","—",IF(F8=K8,"Khớp","KHÁC")) -> Khớp | P8: Tay cầm: hiện tại HALF, HORIZONTAL, LIGHT, THUMB, VERTICAL, nguồn HALF, HORIZONTAL, LASER, LIGHT, THUMB, VERTICAL | Q8: Sửa theo nguồn: Tay cầm
A9: ACE32 | B9: ACE32 | C9: COMPENSATOR, FLASH_HIDER, SUPPRESSOR | D9: HALF, HORIZONTAL, LIGHT, THUMB, VERTICAL | E9: — | F9: 6 | G9: Không có nguồn | L9: =IF($G9="Không có nguồn","—",IF(C9=H9,"Khớp","KHÁC")) -> — | M9: =IF($G9="Không có nguồn","—",IF(D9=I9,"Khớp","KHÁC")) -> — | N9: =IF($G9="Không có nguồn","—",IF(E9=J9,"Khớp","KHÁC")) -> — | O9: =IF($G9="Không có nguồn","—",IF(F9=K9,"Khớp","KHÁC")) -> — | Q9: Giữ nguyên (chưa có nguồn đối chiếu)
A10: AUG | B10: AUG | C10: COMPENSATOR, FLASH_HIDER, SUPPRESSOR | D10: HALF, HORIZONTAL, LIGHT, THUMB, VERTICAL | E10: — | F10: 6 | G10: Chính thức 和平精英 | H10: COMPENSATOR, FLASH_HIDER, SUPPRESSOR | I10: HALF, HORIZONTAL, LASER, LIGHT, THUMB, VERTICAL | J10: — | K10: 6 | L10: =IF($G10="Không có nguồn","—",IF(C10=H10,"Khớp","KHÁC")) -> Khớp | M10: =IF($G10="Không có nguồn","—",IF(D10=I10,"Khớp","KHÁC")) -> KHÁC | N10: =IF($G10="Không có nguồn","—",IF(E10=J10,"Khớp","KHÁC")) -> Khớp | O10: =IF($G10="Không có nguồn","—",IF(F10=K10,"Khớp","KHÁC")) -> Khớp | P10: Tay cầm: hiện tại HALF, HORIZONTAL, LIGHT, THUMB, VERTICAL, nguồn HALF, HORIZONTAL, LASER, LIGHT, THUMB, VERTICAL | Q10: Sửa theo nguồn: Tay cầm
A11: AKM | B11: AKM | C11: COMPENSATOR, FLASH_HIDER, SUPPRESSOR | D11: — | E11: — | F11: 6 | G11: Chính thức 和平精英 | H11: COMPENSATOR, FLASH_HIDER, SUPPRESSOR | I11: — | J11: — | K11: 6 | L11: =IF($G11="Không có nguồn","—",IF(C11=H11,"Khớp","KHÁC")) -> Khớp | M11: =IF($G11="Không có nguồn","—",IF(D11=I11,"Khớp","KHÁC")) -> Khớp | N11: =IF($G11="Không có nguồn","—",IF(E11=J11,"Khớp","KHÁC")) -> Khớp | O11: =IF($G11="Không có nguồn","—",IF(F11=K11,"Khớp","KHÁC")) -> Khớp | Q11: Giữ nguyên (khớp)
A12: Groza | B12: Groza | C12: COMPENSATOR, FLASH_HIDER, SUPPRESSOR | D12: — | E12: — | F12: 6 | G12: Chính thức 和平精英 | H12: SUPPRESSOR | I12: — | J12: — | K12: 6 | L12: =IF($G12="Không có nguồn","—",IF(C12=H12,"Khớp","KHÁC")) -> KHÁC | M12: =IF($G12="Không có nguồn","—",IF(D12=I12,"Khớp","KHÁC")) -> Khớp | N12: =IF($G12="Không có nguồn","—",IF(E12=J12,"Khớp","KHÁC")) -> Khớp | O12: =IF($G12="Không có nguồn","—",IF(F12=K12,"Khớp","KHÁC")) -> Khớp | P12: Nòng: hiện tại COMPENSATOR, FLASH_HIDER, SUPPRESSOR, nguồn SUPPRESSOR | Q12: Sửa theo nguồn: Nòng
A13: FAMAS | B13: FAMAS | C13: COMPENSATOR, FLASH_HIDER, SUPPRESSOR | D13: — | E13: — | F13: 6 | G13: AppMedia (toàn cầu 2022) | H13: COMPENSATOR, FLASH_HIDER, SUPPRESSOR | I13: — | J13: — | K13: 6 | L13: =IF($G13="Không có nguồn","—",IF(C13=H13,"Khớp","KHÁC")) -> Khớp | M13: =IF($G13="Không có nguồn","—",IF(D13=I13,"Khớp","KHÁC")) -> Khớp | N13: =IF($G13="Không có nguồn","—",IF(E13=J13,"Khớp","KHÁC")) -> Khớp | O13: =IF($G13="Không có nguồn","—",IF(F13=K13,"Khớp","KHÁC")) -> Khớp | Q13: Giữ nguyên (khớp)
A14: M762 | B14: Beryl M762 | C14: COMPENSATOR, FLASH_HIDER, SUPPRESSOR | D14: HALF, HORIZONTAL, LIGHT, THUMB, VERTICAL | E14: — | F14: 6 | G14: Chính thức 和平精英 | H14: COMPENSATOR, FLASH_HIDER, SUPPRESSOR | I14: HALF, HORIZONTAL, LASER, LIGHT, THUMB, VERTICAL | J14: — | K14: 6 | L14: =IF($G14="Không có nguồn","—",IF(C14=H14,"Khớp","KHÁC")) -> Khớp | M14: =IF($G14="Không có nguồn","—",IF(D14=I14,"Khớp","KHÁC")) -> KHÁC | N14: =IF($G14="Không có nguồn","—",IF(E14=J14,"Khớp","KHÁC")) -> Khớp | O14: =IF($G14="Không có nguồn","—",IF(F14=K14,"Khớp","KHÁC")) -> Khớp | P14: Tay cầm: hiện tại HALF, HORIZONTAL, LIGHT, THUMB, VERTICAL, nguồn HALF, HORIZONTAL, LASER, LIGHT, THUMB, VERTICAL | Q14: Sửa theo nguồn: Tay cầm
A15: M16 | B15: M16A4 | C15: COMPENSATOR, FLASH_HIDER, SUPPRESSOR | D15: — | E15: — | F15: 6 | G15: Chính thức 和平精英 | H15: COMPENSATOR, FLASH_HIDER, SUPPRESSOR | I15: — | J15: GENERAL | K15: 6 | L15: =IF($G15="Không có nguồn","—",IF(C15=H15,"Khớp","KHÁC")) -> Khớp | M15: =IF($G15="Không có nguồn","—",IF(D15=I15,"Khớp","KHÁC")) -> Khớp | N15: =IF($G15="Không có nguồn","—",IF(E15=J15,"Khớp","KHÁC")) -> KHÁC | O15: =IF($G15="Không có nguồn","—",IF(F15=K15,"Khớp","KHÁC")) -> Khớp | P15: Báng: hiện tại —, nguồn GENERAL | Q15: Sửa theo nguồn: Báng
A16: MK47 | B16: Mk47 Mutant | C16: COMPENSATOR, FLASH_HIDER, SUPPRESSOR | D16: HALF, HORIZONTAL, LIGHT, THUMB, VERTICAL | E16: — | F16: 6 | G16: Chính thức 和平精英 | H16: COMPENSATOR, FLASH_HIDER, SUPPRESSOR | I16: HALF, HORIZONTAL, LASER, LIGHT, THUMB, VERTICAL | J16: GENERAL | K16: 6 | L16: =IF($G16="Không có nguồn","—",IF(C16=H16,"Khớp","KHÁC")) -> Khớp | M16: =IF($G16="Không có nguồn","—",IF(D16=I16,"Khớp","KHÁC")) -> KHÁC | N16: =IF($G16="Không có nguồn","—",IF(E16=J16,"Khớp","KHÁC")) -> KHÁC | O16: =IF($G16="Không có nguồn","—",IF(F16=K16,"Khớp","KHÁC")) -> Khớp | P16: Tay cầm: hiện tại HALF, HORIZONTAL, LIGHT, THUMB, VERTICAL, nguồn HALF, HORIZONTAL, LASER, LIGHT, THUMB, VERTICAL; Báng: hiện tại —, nguồn GENERAL | Q16: Sửa theo nguồn: Tay cầm; Báng
A17: UZI | B17: Micro UZI | C17: COMPENSATOR, FLASH_HIDER, SUPPRESSOR | D17: — | E17: GENERAL | F17: 1 | G17: Chính thức 和平精英 | H17: COMPENSATOR, FLASH_HIDER, SUPPRESSOR | I17: — | J17: GENERAL | K17: 1 | L17: =IF($G17="Không có nguồn","—",IF(C17=H17,"Khớp","KHÁC")) -> Khớp | M17: =IF($G17="Không có nguồn","—",IF(D17=I17,"Khớp","KHÁC")) -> Khớp | N17: =IF($G17="Không có nguồn","—",IF(E17=J17,"Khớp","KHÁC")) -> Khớp | O17: =IF($G17="Không có nguồn","—",IF(F17=K17,"Khớp","KHÁC")) -> Khớp | Q17: Giữ nguyên (khớp)
A18: Vector | B18: Vector | C18: COMPENSATOR, FLASH_HIDER, SUPPRESSOR | D18: HALF, HORIZONTAL, LIGHT, THUMB, VERTICAL | E18: GENERAL | F18: 6 | G18: Chính thức 和平精英 | H18: COMPENSATOR, FLASH_HIDER, SUPPRESSOR | I18: HALF, LASER, LIGHT, VERTICAL | J18: GENERAL | K18: 6 | L18: =IF($G18="Không có nguồn","—",IF(C18=H18,"Khớp","KHÁC")) -> Khớp | M18: =IF($G18="Không có nguồn","—",IF(D18=I18,"Khớp","KHÁC")) -> KHÁC | N18: =IF($G18="Không có nguồn","—",IF(E18=J18,"Khớp","KHÁC")) -> Khớp | O18: =IF($G18="Không có nguồn","—",IF(F18=K18,"Khớp","KHÁC")) -> Khớp | P18: Tay cầm: hiện tại HALF, HORIZONTAL, LIGHT, THUMB, VERTICAL, nguồn HALF, LASER, LIGHT, VERTICAL | Q18: Sửa theo nguồn: Tay cầm
A19: UMP45 | B19: UMP45 | C19: COMPENSATOR, FLASH_HIDER, SUPPRESSOR | D19: HALF, HORIZONTAL, LIGHT, THUMB, VERTICAL | E19: — | F19: 6 | G19: Chính thức 和平精英 | H19: COMPENSATOR, FLASH_HIDER, SUPPRESSOR | I19: HALF, HORIZONTAL, LASER, LIGHT, THUMB, VERTICAL | J19: — | K19: 6 | L19: =IF($G19="Không có nguồn","—",IF(C19=H19,"Khớp","KHÁC")) -> Khớp | M19: =IF($G19="Không có nguồn","—",IF(D19=I19,"Khớp","KHÁC")) -> KHÁC | N19: =IF($G19="Không có nguồn","—",IF(E19=J19,"Khớp","KHÁC")) -> Khớp | O19: =IF($G19="Không có nguồn","—",IF(F19=K19,"Khớp","KHÁC")) -> Khớp | P19: Tay cầm: hiện tại HALF, HORIZONTAL, LIGHT, THUMB, VERTICAL, nguồn HALF, HORIZONTAL, LASER, LIGHT, THUMB, VERTICAL | Q19: Sửa theo nguồn: Tay cầm
A20: Thomson | B20: Tommy Gun (Thompson) | C20: SUPPRESSOR | D20: — | E20: — | F20: 1 | G20: Chính thức 和平精英 | H20: SUPPRESSOR | I20: VERTICAL | J20: — | K20: 1 | L20: =IF($G20="Không có nguồn","—",IF(C20=H20,"Khớp","KHÁC")) -> Khớp | M20: =IF($G20="Không có nguồn","—",IF(D20=I20,"Khớp","KHÁC")) -> KHÁC | N20: =IF($G20="Không có nguồn","—",IF(E20=J20,"Khớp","KHÁC")) -> Khớp | O20: =IF($G20="Không có nguồn","—",IF(F20=K20,"Khớp","KHÁC")) -> Khớp | P20: Tay cầm: hiện tại —, nguồn VERTICAL | Q20: Sửa theo nguồn: Tay cầm
A21: Kar98K | B21: Kar98k | C21: COMPENSATOR, FLASH_HIDER, SUPPRESSOR | D21: — | E21: — | F21: 8 | G21: Chính thức 和平精英 | H21: COMPENSATOR, FLASH_HIDER, SUPPRESSOR | I21: — | J21: — | K21: 8 | L21: =IF($G21="Không có nguồn","—",IF(C21=H21,"Khớp","KHÁC")) -> Khớp | M21: =IF($G21="Không có nguồn","—",IF(D21=I21,"Khớp","KHÁC")) -> Khớp | N21: =IF($G21="Không có nguồn","—",IF(E21=J21,"Khớp","KHÁC")) -> Khớp | O21: =IF($G21="Không có nguồn","—",IF(F21=K21,"Khớp","KHÁC")) -> Khớp | P21: | báng ngoài app: Túi đạn (Bullet Loops), Ốp má (Cheek Pad) | Q21: Giữ nguyên (khớp)
A22: M24 | B22: M24 | C22: COMPENSATOR, FLASH_HIDER, SUPPRESSOR | D22: — | E22: — | F22: 8 | G22: Chính thức 和平精英 | H22: COMPENSATOR, FLASH_HIDER, SUPPRESSOR | I22: — | J22: — | K22: 8 | L22: =IF($G22="Không có nguồn","—",IF(C22=H22,"Khớp","KHÁC")) -> Khớp | M22: =IF($G22="Không có nguồn","—",IF(D22=I22,"Khớp","KHÁC")) -> Khớp | N22: =IF($G22="Không có nguồn","—",IF(E22=J22,"Khớp","KHÁC")) -> Khớp | O22: =IF($G22="Không có nguồn","—",IF(F22=K22,"Khớp","KHÁC")) -> Khớp | P22: | báng ngoài app: Ốp má (Cheek Pad) | Q22: Giữ nguyên (khớp)
A23: AWM | B23: AWM | C23: COMPENSATOR, FLASH_HIDER, SUPPRESSOR | D23: — | E23: — | F23: 8 | G23: Chính thức 和平精英 | H23: COMPENSATOR, FLASH_HIDER, SUPPRESSOR | I23: — | J23: — | K23: 8 | L23: =IF($G23="Không có nguồn","—",IF(C23=H23,"Khớp","KHÁC")) -> Khớp | M23: =IF($G23="Không có nguồn","—",IF(D23=I23,"Khớp","KHÁC")) -> Khớp | N23: =IF($G23="Không có nguồn","—",IF(E23=J23,"Khớp","KHÁC")) -> Khớp | O23: =IF($G23="Không có nguồn","—",IF(F23=K23,"Khớp","KHÁC")) -> Khớp | P23: | báng ngoài app: Ốp má (Cheek Pad) | Q23: Giữ nguyên (khớp)
A24: SKS | B24: SKS | C24: COMPENSATOR, FLASH_HIDER, SUPPRESSOR | D24: HALF, HORIZONTAL, LIGHT, THUMB, VERTICAL | E24: — | F24: 8 | G24: Chính thức 和平精英 | H24: COMPENSATOR, FLASH_HIDER, SUPPRESSOR | I24: HALF, HORIZONTAL, LASER, LIGHT, THUMB, VERTICAL | J24: — | K24: 8 | L24: =IF($G24="Không có nguồn","—",IF(C24=H24,"Khớp","KHÁC")) -> Khớp | M24: =IF($G24="Không có nguồn","—",IF(D24=I24,"Khớp","KHÁC")) -> KHÁC | N24: =IF($G24="Không có nguồn","—",IF(E24=J24,"Khớp","KHÁC")) -> Khớp | O24: =IF($G24="Không có nguồn","—",IF(F24=K24,"Khớp","KHÁC")) -> Khớp | P24: Tay cầm: hiện tại HALF, HORIZONTAL, LIGHT, THUMB, VERTICAL, nguồn HALF, HORIZONTAL, LASER, LIGHT, THUMB, VERTICAL | báng ngoài app: Ốp má (Cheek Pad) | Q24: Sửa theo nguồn: Tay cầm
A25: SLR | B25: SLR | C25: COMPENSATOR, FLASH_HIDER, SUPPRESSOR | D25: HALF, HORIZONTAL, LIGHT, THUMB, VERTICAL | E25: — | F25: 8 | G25: Chính thức 和平精英 | H25: COMPENSATOR, FLASH_HIDER, SUPPRESSOR | I25: — | J25: — | K25: 8 | L25: =IF($G25="Không có nguồn","—",IF(C25=H25,"Khớp","KHÁC")) -> Khớp | M25: =IF($G25="Không có nguồn","—",IF(D25=I25,"Khớp","KHÁC")) -> KHÁC | N25: =IF($G25="Không có nguồn","—",IF(E25=J25,"Khớp","KHÁC")) -> Khớp | O25: =IF($G25="Không có nguồn","—",IF(F25=K25,"Khớp","KHÁC")) -> Khớp | P25: Tay cầm: hiện tại HALF, HORIZONTAL, LIGHT, THUMB, VERTICAL, nguồn — | báng ngoài app: Ốp má (Cheek Pad) | Q25: Sửa theo nguồn: Tay cầm
A26: MK14 | B26: Mk14 | C26: COMPENSATOR, FLASH_HIDER, SUPPRESSOR | D26: HALF, HORIZONTAL, LIGHT, THUMB, VERTICAL | E26: — | F26: 8 | G26: Chính thức 和平精英 | H26: COMPENSATOR, FLASH_HIDER, SUPPRESSOR | I26: — | J26: — | K26: 8 | L26: =IF($G26="Không có nguồn","—",IF(C26=H26,"Khớp","KHÁC")) -> Khớp | M26: =IF($G26="Không có nguồn","—",IF(D26=I26,"Khớp","KHÁC")) -> KHÁC | N26: =IF($G26="Không có nguồn","—",IF(E26=J26,"Khớp","KHÁC")) -> Khớp | O26: =IF($G26="Không có nguồn","—",IF(F26=K26,"Khớp","KHÁC")) -> Khớp | P26: Tay cầm: hiện tại HALF, HORIZONTAL, LIGHT, THUMB, VERTICAL, nguồn — | báng ngoài app: Ốp má (Cheek Pad) | Q26: Sửa theo nguồn: Tay cầm
A27: Mini14 | B27: Mini14 | C27: COMPENSATOR, FLASH_HIDER, SUPPRESSOR | D27: — | E27: — | F27: 8 | G27: Chính thức 和平精英 | H27: COMPENSATOR, FLASH_HIDER, SUPPRESSOR | I27: — | J27: — | K27: 8 | L27: =IF($G27="Không có nguồn","—",IF(C27=H27,"Khớp","KHÁC")) -> Khớp | M27: =IF($G27="Không có nguồn","—",IF(D27=I27,"Khớp","KHÁC")) -> Khớp | N27: =IF($G27="Không có nguồn","—",IF(E27=J27,"Khớp","KHÁC")) -> Khớp | O27: =IF($G27="Không có nguồn","—",IF(F27=K27,"Khớp","KHÁC")) -> Khớp | Q27: Giữ nguyên (khớp)
A28: VSS | B28: VSS | C28: COMPENSATOR, FLASH_HIDER, SUPPRESSOR | D28: — | E28: — | F28: 8 | G28: Chính thức 和平精英 | H28: — | I28: — | J28: — | K28: 0 | L28: =IF($G28="Không có nguồn","—",IF(C28=H28,"Khớp","KHÁC")) -> KHÁC | M28: =IF($G28="Không có nguồn","—",IF(D28=I28,"Khớp","KHÁC")) -> Khớp | N28: =IF($G28="Không có nguồn","—",IF(E28=J28,"Khớp","KHÁC")) -> Khớp | O28: =IF($G28="Không có nguồn","—",IF(F28=K28,"Khớp","KHÁC")) -> KHÁC | P28: Nòng: hiện tại COMPENSATOR, FLASH_HIDER, SUPPRESSOR, nguồn —; Ống ngắm: hiện tại ≤8x, nguồn không lắp được ống ngắm | báng ngoài app: Ốp má (Cheek Pad) | Q28: Sửa theo nguồn: Nòng; Ống ngắm
A29: QBU | B29: QBU | C29: COMPENSATOR, FLASH_HIDER, SUPPRESSOR | D29: — | E29: — | F29: 8 | G29: Chính thức 和平精英 | H29: COMPENSATOR, FLASH_HIDER, SUPPRESSOR | I29: — | J29: — | K29: 8 | L29: =IF($G29="Không có nguồn","—",IF(C29=H29,"Khớp","KHÁC")) -> Khớp | M29: =IF($G29="Không có nguồn","—",IF(D29=I29,"Khớp","KHÁC")) -> Khớp | N29: =IF($G29="Không có nguồn","—",IF(E29=J29,"Khớp","KHÁC")) -> Khớp | O29: =IF($G29="Không có nguồn","—",IF(F29=K29,"Khớp","KHÁC")) -> Khớp | Q29: Giữ nguyên (khớp)
A30: MK12 | B30: MK12 | C30: COMPENSATOR, FLASH_HIDER, SUPPRESSOR | D30: — | E30: — | F30: 8 | G30: AppMedia (toàn cầu 2022) | H30: COMPENSATOR, FLASH_HIDER, SUPPRESSOR | I30: — | J30: — | K30: 8 | L30: =IF($G30="Không có nguồn","—",IF(C30=H30,"Khớp","KHÁC")) -> Khớp | M30: =IF($G30="Không có nguồn","—",IF(D30=I30,"Khớp","KHÁC")) -> Khớp | N30: =IF($G30="Không có nguồn","—",IF(E30=J30,"Khớp","KHÁC")) -> Khớp | O30: =IF($G30="Không có nguồn","—",IF(F30=K30,"Khớp","KHÁC")) -> Khớp | Q30: Giữ nguyên (khớp)
A31: DP28 | B31: DP-28 | C31: — | D31: — | E31: — | F31: 6 | G31: Chính thức 和平精英 | H31: — | I31: — | J31: — | K31: 6 | L31: =IF($G31="Không có nguồn","—",IF(C31=H31,"Khớp","KHÁC")) -> Khớp | M31: =IF($G31="Không có nguồn","—",IF(D31=I31,"Khớp","KHÁC")) -> Khớp | N31: =IF($G31="Không có nguồn","—",IF(E31=J31,"Khớp","KHÁC")) -> Khớp | O31: =IF($G31="Không có nguồn","—",IF(F31=K31,"Khớp","KHÁC")) -> Khớp | Q31: Giữ nguyên (khớp)
A32: S1897 | B32: S1897 | C32: — | D32: — | E32: — | F32: không giới hạn | G32: Chính thức 和平精英 | H32: — | I32: — | J32: — | K32: 0 | L32: =IF($G32="Không có nguồn","—",IF(C32=H32,"Khớp","KHÁC")) -> Khớp | M32: =IF($G32="Không có nguồn","—",IF(D32=I32,"Khớp","KHÁC")) -> Khớp | N32: =IF($G32="Không có nguồn","—",IF(E32=J32,"Khớp","KHÁC")) -> Khớp | O32: =IF($G32="Không có nguồn","—",IF(F32=K32,"Khớp","KHÁC")) -> KHÁC | P32: Ống ngắm: hiện tại không giới hạn, nguồn không lắp được ống ngắm | nòng ngoài app: Choke (bộ thu hẹp đạn), Duckbill (mõ vịt); báng ngoài app: Túi đạn (Bullet Loops) | Q32: Sửa theo nguồn: Ống ngắm
A33: S686 | B33: S686 | C33: — | D33: — | E33: — | F33: không giới hạn | G33: Chính thức 和平精英 | H33: — | I33: — | J33: — | K33: 0 | L33: =IF($G33="Không có nguồn","—",IF(C33=H33,"Khớp","KHÁC")) -> Khớp | M33: =IF($G33="Không có nguồn","—",IF(D33=I33,"Khớp","KHÁC")) -> Khớp | N33: =IF($G33="Không có nguồn","—",IF(E33=J33,"Khớp","KHÁC")) -> Khớp | O33: =IF($G33="Không có nguồn","—",IF(F33=K33,"Khớp","KHÁC")) -> KHÁC | P33: Ống ngắm: hiện tại không giới hạn, nguồn không lắp được ống ngắm | nòng ngoài app: Choke (bộ thu hẹp đạn); báng ngoài app: Túi đạn (Bullet Loops) | Q33: Sửa theo nguồn: Ống ngắm
A34: S12K | B34: S12K | C34: COMPENSATOR, FLASH_HIDER, SUPPRESSOR | D34: — | E34: — | F34: 6 | G34: Chính thức 和平精英 | H34: COMPENSATOR, FLASH_HIDER, SUPPRESSOR | I34: — | J34: — | K34: 6 | L34: =IF($G34="Không có nguồn","—",IF(C34=H34,"Khớp","KHÁC")) -> Khớp | M34: =IF($G34="Không có nguồn","—",IF(D34=I34,"Khớp","KHÁC")) -> Khớp | N34: =IF($G34="Không có nguồn","—",IF(E34=J34,"Khớp","KHÁC")) -> Khớp | O34: =IF($G34="Không có nguồn","—",IF(F34=K34,"Khớp","KHÁC")) -> Khớp | P34: | nòng ngoài app: Duckbill (mõ vịt) | Q34: Giữ nguyên (khớp)

Sheet Chính thức 和平精英 (45 súng)
A1: Dữ liệu chính thức của Tencent: kho vũ khí 和平精英 (45 vũ khí)
A2: Nguồn: https://gp.qq.com/zlkdatasys/data_zlk_hpjywqzlk1.json (trang https://gp.qq.com/cp/a20251120arsenal/index.html). Cột "nguyên văn" là câu gốc tiếng Trung của Tencent. Trang ghi: dữ liệu do người chơi thu thập, lấy thông số trong game làm chuẩn.
A4: Loại | B4: Tên (Tencent) | C4: Mã (app) | D4: ID | E4: Đạn | F4: Đầu nòng: nguyên văn | G4: Băng đạn: nguyên văn | H4: Ống ngắm: nguyên văn | I4: Tay cầm/báng: nguyên văn | J4: Nòng (app) | K4: Tay cầm (app) | L4: Báng (app) | M4: Ngoài danh sách app | N4: Ống ngắm tối đa | O4: Ống ngắm bên
A5: Súng trường tấn công (AR) | B5: AKM | C5: AKM | D5: 101001 | E5: 7.62mm | F5: 步枪补偿器、步枪消焰器、步枪消音器； | G5: 步枪扩容弹匣、步枪快速弹匣、步枪快速扩容弹匣； | H5: 6倍镜、4倍镜、3倍镜、2倍镜、全息瞄准镜、红点瞄准镜、侧瞄准镜 | J5: COMPENSATOR, FLASH_HIDER, SUPPRESSOR | K5: — | L5: — | M5: — | N5: 6 | O5: có
A6: Súng trường tấn công (AR) | B6: M16A4 | C6: M16 | D6: 101002 | E6: 5.56mm | F6: 步枪补偿器、步枪消焰器、步枪消音器； | G6: 步枪扩容弹匣、步枪快速弹匣、步枪快速扩容弹匣； | H6: 6倍镜、4倍镜、3倍镜、2倍镜、全息瞄准镜、红点瞄准镜、侧瞄准镜； | I6: 战术枪托 | J6: COMPENSATOR, FLASH_HIDER, SUPPRESSOR | K6: — | L6: GENERAL | M6: — | N6: 6 | O6: có
A7: Súng trường tấn công (AR) | B7: M416 | C7: M416 | D7: 101004 | E7: 5.56mm | F7: 步枪补偿器、步枪消焰器、步枪消音器； | G7: 步枪扩容弹匣、步枪快速弹匣、步枪快速扩容弹匣； | H7: 6倍镜、4倍镜、3倍镜、2倍镜、全息瞄准镜、红点瞄准镜、侧瞄准镜； | I7: 战术枪托、直角前握把、垂直握把、拇指握把、轻型握把、半截式握把、激光瞄准镜 | J7: COMPENSATOR, FLASH_HIDER, SUPPRESSOR | K7: HALF, HORIZONTAL, LASER, LIGHT, THUMB, VERTICAL | L7: GENERAL | M7: — | N7: 6 | O7: có
A8: Súng trường tấn công (AR) | B8: SCAR-L | C8: Scar | D8: 101003 | E8: 5.56mm | F8: 步枪补偿器、步枪消焰器、步枪消音器； | G8: 步枪扩容弹匣、步枪快速弹匣、步枪快速扩容弹匣； | H8: 6倍镜、4倍镜、3倍镜、2倍镜、全息瞄准镜、红点瞄准镜、侧瞄准镜； | I8: 直角前握把、垂直握把、拇指握把、轻型握把、半截式握把、激光瞄准器 | J8: COMPENSATOR, FLASH_HIDER, SUPPRESSOR | K8: HALF, HORIZONTAL, LASER, LIGHT, THUMB, VERTICAL | L8: — | M8: — | N8: 6 | O8: có
A9: Súng trường tấn công (AR) | B9: Groza | C9: Groza | D9: 101005 | E9: 7.62mm | F9: 步枪消音器； | G9: 步枪扩容弹匣、步枪快速弹匣、步枪快速扩容弹匣； | H9: 6倍镜、4倍镜、3倍镜、2倍镜、全息瞄准镜、红点瞄准镜、侧瞄准镜 | J9: SUPPRESSOR | K9: — | L9: — | M9: — | N9: 6 | O9: có
A10: Súng trường tấn công (AR) | B10: AUG | C10: AUG | D10: 101006 | E10: 5.56mm | F10: 步枪补偿器、步枪消焰器、步枪消音器； | G10: 步枪扩容弹匣、步枪快速弹匣、步枪快速扩容弹匣； | H10: 6倍镜、4倍镜、3倍镜、2倍镜、全息瞄准镜、红点瞄准镜、侧瞄准镜； | I10: 直角前握把、垂直握把、拇指握把、轻型握把、半截式握把、激光瞄准器 | J10: COMPENSATOR, FLASH_HIDER, SUPPRESSOR | K10: HALF, HORIZONTAL, LASER, LIGHT, THUMB, VERTICAL | L10: — | M10: — | N10: 6 | O10: có
A11: Súng trường tấn công (AR) | B11: QBZ | C11: QBZ | D11: 101007 | E11: 5.56mm | F11: 步枪补偿器、步枪消焰器、步枪消音器； | G11: 步枪扩容弹匣、步枪快速弹匣、步枪快速扩容弹匣； | H11: 6倍镜、4倍镜、3倍镜、2倍镜、全息瞄准镜、红点瞄准镜、侧瞄准镜； | I11: 直角前握把、垂直握把、拇指握把、轻型握把、半截式握把、激光瞄准器 | J11: COMPENSATOR, FLASH_HIDER, SUPPRESSOR | K11: HALF, HORIZONTAL, LASER, LIGHT, THUMB, VERTICAL | L11: — | M11: — | N11: 6 | O11: có
A12: Súng trường tấn công (AR) | B12: M762 | C12: M762 | D12: 101008 | E12: 7.62mm | F12: 步枪补偿器、步枪消焰器、步枪消音器； | G12: 步枪扩容弹匣、步枪快速弹匣、步枪快速扩容弹匣； | H12: 6倍镜、4倍镜、3倍镜、2倍镜、全息瞄准镜、红点瞄准镜、侧瞄准镜； | I12: 直角前握把、垂直握把、拇指握把、轻型握把、半截式握把、激光瞄准器 | J12: COMPENSATOR, FLASH_HIDER, SUPPRESSOR | K12: HALF, HORIZONTAL, LASER, LIGHT, THUMB, VERTICAL | L12: — | M12: — | N12: 6 | O12: có
A13: Súng trường tấn công (AR) | B13: MK47 | C13: MK47 | D13: 101009 | E13: 7.62mm | F13: 步枪补偿器、步枪消焰器、步枪消音器； | G13: 步枪扩容弹匣、步枪快速弹匣、步枪快速扩容弹匣； | H13: 6倍镜、4倍镜、3倍镜、2倍镜、全息瞄准镜、红点瞄准镜、侧瞄准镜； | I13: 战术枪托、直角前握把、垂直握把、拇指握把、轻型握把、半截式握把、激光瞄准器 | J13: COMPENSATOR, FLASH_HIDER, SUPPRESSOR | K13: HALF, HORIZONTAL, LASER, LIGHT, THUMB, VERTICAL | L13: GENERAL | M13: — | N13: 6 | O13: có
A14: Súng trường tấn công (AR) | B14: G36C | C14: G36C | D14: 101010 | E14: 5.56mm | F14: 步枪补偿器、步枪消焰器、步枪消音器； | G14: 步枪扩容弹匣、步枪快速弹匣、步枪快速扩容弹匣； | H14: 6倍镜、4倍镜、3倍镜、2倍镜、全息瞄准镜、红点瞄准镜、侧瞄准镜； | I14: 直角前握把、垂直握把、拇指握把、轻型握把、半截式握把、激光瞄准器 | J14: COMPENSATOR, FLASH_HIDER, SUPPRESSOR | K14: HALF, HORIZONTAL, LASER, LIGHT, THUMB, VERTICAL | L14: — | M14: — | N14: 6 | O14: có
A15: Súng trường xạ thủ (DMR) | B15: VSS | C15: VSS | D15: 103005 | E15: 9mm | G15: 狙击枪/步枪扩容弹匣、狙击枪/步枪快速弹匣、狙击枪/步枪快速扩容弹匣； | I15: 托腮板； | J15: — | K15: — | L15: — | M15: Ốp má (Cheek Pad) | N15: 0 | O15: không
A16: Súng trường xạ thủ (DMR) | B16: SKS | C16: SKS | D16: 103004 | E16: 7.62mm | F16: 狙击枪/步枪口补偿器、狙击枪/步枪消焰器、狙击枪/步枪消音器； | G16: 狙击枪/步枪扩容弹匣、狙击枪/步枪快速弹匣、狙击枪/步枪快速扩容弹匣； | H16: 8倍镜、6倍镜、4倍镜、3倍镜、2倍镜、全息瞄准镜、红点瞄准镜、侧瞄准镜； | I16: 托腮板、直角前握把、垂直握把、拇指握把、轻型握把、半截式握把、激光瞄准器； | J16: COMPENSATOR, FLASH_HIDER, SUPPRESSOR | K16: HALF, HORIZONTAL, LASER, LIGHT, THUMB, VERTICAL | L16: — | M16: Ốp má (Cheek Pad) | N16: 8 | O16: có
A17: Súng trường xạ thủ (DMR) | B17: Mk14 | C17: MK14 | D17: 103007 | E17: 7.62mm | F17: 狙击枪/步枪口补偿器、狙击枪/步枪消焰器、狙击枪/步枪消音器； | G17: 狙击枪/步枪扩容弹匣、狙击枪/步枪快速弹匣、狙击枪/步枪快速扩容弹匣； | H17: 8倍镜、6倍镜、4倍镜、3倍镜、2倍镜、全息瞄准镜、红点瞄准镜、侧瞄准镜； | I17: 托腮板； | J17: COMPENSATOR, FLASH_HIDER, SUPPRESSOR | K17: — | L17: — | M17: Ốp má (Cheek Pad) | N17: 8 | O17: có
A18: Súng trường xạ thủ (DMR) | B18: Mini14 | C18: Mini14 | D18: 103006 | E18: 5.56mm | F18: 狙击枪/步枪口补偿器、狙击枪/步枪消焰器、狙击枪/步枪消音器； | G18: 狙击枪/步枪扩容弹匣、狙击枪/步枪快速弹匣、狙击枪/步枪快速扩容弹匣； | H18: 8倍镜、6倍镜、4倍镜、3倍镜、2倍镜、全息瞄准镜、红点瞄准镜、侧瞄准镜； | J18: COMPENSATOR, FLASH_HIDER, SUPPRESSOR | K18: — | L18: — | M18: — | N18: 8 | O18: có
A19: Súng trường xạ thủ (DMR) | B19: SLR | C19: SLR | D19: 103009 | E19: 7.62mm | F19: 狙击枪/步枪口补偿器、狙击枪/步枪消焰器、狙击枪/步枪消音器； | G19: 狙击枪/步枪扩容弹匣、狙击枪/步枪快速弹匣、狙击枪/步枪快速扩容弹匣； | H19: 8倍镜、6倍镜、4倍镜、3倍镜、2倍镜、全息瞄准镜、红点瞄准镜、侧瞄准镜； | I19: 托腮板； | J19: COMPENSATOR, FLASH_HIDER, SUPPRESSOR | K19: — | L19: — | M19: Ốp má (Cheek Pad) | N19: 8 | O19: có
A20: Súng trường xạ thủ (DMR) | B20: QBU | C20: QBU | D20: 103010 | E20: 5.56mm | F20: 狙击枪/步枪口补偿器、狙击枪/步枪消焰器、狙击枪/步枪消音器； | G20: 狙击枪/步枪扩容弹匣、狙击枪/步枪快速弹匣、狙击枪/步枪快速扩容弹匣； | H20: 8倍镜、6倍镜、4倍镜、3倍镜、2倍镜、全息瞄准镜、红点瞄准镜、侧瞄准镜； | J20: COMPENSATOR, FLASH_HIDER, SUPPRESSOR | K20: — | L20: — | M20: — | N20: 8 | O20: có
A21: Súng bắn tỉa (SR) | B21: AWM | C21: AWM | D21: 103003 | E21: 马格南 | F21: 狙击枪口补偿器、狙击枪消焰器、狙击枪消音器； | G21: 狙击枪扩容弹夹、狙击枪快速弹夹、狙击枪快速扩容弹夹； | H21: 8倍镜、6倍镜、4倍镜、3倍镜、2倍镜、全息瞄准镜、红点瞄准镜、侧瞄准镜； | I21: 托腮板 | J21: COMPENSATOR, FLASH_HIDER, SUPPRESSOR | K21: — | L21: — | M21: Ốp má (Cheek Pad) | N21: 8 | O21: có
A22: Súng bắn tỉa (SR) | B22: Kar98k | C22: Kar98K | D22: 103001 | E22: 7.62mm | F22: 狙击枪口补偿器、狙击枪消焰器、狙击枪消音器； | H22: 8倍镜、6倍镜、4倍镜、3倍镜、2倍镜、全息瞄准镜、红点瞄准镜、侧瞄准镜； | I22: 子弹袋、托腮板 | J22: COMPENSATOR, FLASH_HIDER, SUPPRESSOR | K22: — | L22: — | M22: Túi đạn (Bullet Loops), Ốp má (Cheek Pad) | N22: 8 | O22: có
A23: Súng bắn tỉa (SR) | B23: M24 | C23: M24 | D23: 103002 | E23: 7.62mm | F23: 狙击枪口补偿器、狙击枪消焰器、狙击枪消音器； | G23: 狙击枪扩容弹匣、狙击枪快速弹匣、狙击枪快速扩容弹匣； | H23: 8倍镜、6倍镜、4倍镜、3倍镜、2倍镜、全息瞄准镜、红点瞄准镜、侧瞄准镜； | I23: 托腮板 | J23: COMPENSATOR, FLASH_HIDER, SUPPRESSOR | K23: — | L23: — | M23: Ốp má (Cheek Pad) | N23: 8 | O23: có
A24: Súng bắn tỉa (SR) | B24: win94 | C24: Win94 | D24: 103008 | E24: .45口径 | I24: 子弹袋 | J24: — | K24: — | L24: — | M24: Túi đạn (Bullet Loops) | N24: 0 | O24: không
A25: Súng tiểu liên (SMG) | B25: UZI | C25: UZI | D25: 102001 | E25: 9mm | F25: 冲锋枪枪口补偿器、冲锋枪消焰器、冲锋枪消音器； | G25: 冲锋枪扩容弹匣、冲锋枪快速弹匣、冲锋枪快速扩容弹匣； | H25: 全息瞄准镜、红点瞄准镜； | I25: 枪托 | J25: COMPENSATOR, FLASH_HIDER, SUPPRESSOR | K25: — | L25: GENERAL | M25: — | N25: 1 | O25: không
A26: Súng tiểu liên (SMG) | B26: 汤姆逊 | C26: Thomson | D26: 102004 | E26: .45口径 | F26: 冲锋枪消音器； | G26: 冲锋枪扩容弹匣、冲锋枪快速弹匣、冲锋枪快速扩容弹匣； | H26: 全息瞄准镜、红点瞄准镜； | I26: 垂直握把 | J26: SUPPRESSOR | K26: VERTICAL | L26: — | M26: — | N26: 1 | O26: không
A27: Súng tiểu liên (SMG) | B27: UMP45 | C27: UMP45 | D27: 102002 | E27: .45口径 | F27: 冲锋枪枪口补偿器、冲锋枪消焰器、冲锋枪消音器； | G27: 冲锋枪扩容弹匣、冲锋枪快速弹匣、冲锋枪快速扩容弹匣； | H27: 6倍镜、4倍镜、3倍镜、2倍镜、全息瞄准镜、红点瞄准镜、侧瞄准镜； | I27: 直角前握把、垂直握把、拇指握把、轻型握把、半截式握把、激光瞄准器 | J27: COMPENSATOR, FLASH_HIDER, SUPPRESSOR | K27: HALF, HORIZONTAL, LASER, LIGHT, THUMB, VERTICAL | L27: — | M27: — | N27: 6 | O27: có
A28: Súng tiểu liên (SMG) | B28: Vector | C28: Vector | D28: 102003 | E28: 9mm | F28: 冲锋枪枪口补偿器、冲锋枪消焰器、冲锋枪消音器； | G28: 冲锋枪扩容弹匣、冲锋枪快速弹匣、冲锋枪快速扩容弹匣； | H28: 6倍镜、4倍镜、3倍镜、2倍镜、全息瞄准镜、红点瞄准镜、侧瞄准镜； | I28: 战术枪托、垂直握把、轻型握把、半截式握把、激光瞄准器 | J28: COMPENSATOR, FLASH_HIDER, SUPPRESSOR | K28: HALF, LASER, LIGHT, VERTICAL | L28: GENERAL | M28: — | N28: 6 | O28: có
A29: Súng tiểu liên (SMG) | B29: 野牛冲锋枪 | C29: Bison | D29: 102005 | E29: 9mm | F29: 冲锋枪枪口补偿器、冲锋枪消焰器、冲锋枪消音器； | H29: 6倍镜、4倍镜、3倍镜、2倍镜、全息瞄准镜、红点瞄准镜、侧瞄准镜 | J29: COMPENSATOR, FLASH_HIDER, SUPPRESSOR | K29: — | L29: — | M29: — | N29: 6 | O29: có
A30: Shotgun (SG) | B30: S12K | C30: S12K | D30: 104003 | E30: 12号口径 | F30: 步枪补偿器、步枪消焰器、步枪消音器、鸭嘴枪口； | G30: 步枪扩容弹匣、步枪快速弹匣、步枪快速扩容弹匣； | H30: 6倍镜、4倍镜、3倍镜、2倍镜、全息瞄准镜、红点瞄准镜、侧瞄准镜 | J30: COMPENSATOR, FLASH_HIDER, SUPPRESSOR | K30: — | L30: — | M30: Duckbill (mõ vịt) | N30: 6 | O30: có
A31: Shotgun (SG) | B31: S1897 | C31: S1897 | D31: 104002 | E31: 12号口径 | F31: 霰弹收束器、鸭嘴枪口； | I31: 子弹袋 | J31: — | K31: — | L31: — | M31: Choke (bộ thu hẹp đạn), Duckbill (mõ vịt), Túi đạn (Bullet Loops) | N31: 0 | O31: không
A32: Shotgun (SG) | B32: S686 | C32: S686 | D32: 104001 | E32: 12号口径 | F32: 霰弹收束器； | I32: 子弹袋 | J32: — | K32: — | L32: — | M32: Choke (bộ thu hẹp đạn), Túi đạn (Bullet Loops) | N32: 0 | O32: không
A33: Shotgun (SG) | B33: DBS | C33: DBS | D33: 104004 | E33: 12号口径 | H33: 6倍镜、4倍镜、3倍镜、2倍镜、全息瞄准镜、红点瞄准镜、侧瞄准镜 | J33: — | K33: — | L33: — | M33: — | N33: 6 | O33: có
A34: Súng máy (LMG) | B34: M249 | C34: M249 | D34: 105001 | E34: 5.56mm | H34: 6倍镜、4倍镜、3倍镜、2倍镜、全息瞄准镜、红点瞄准镜、侧瞄准镜 | J34: — | K34: — | L34: — | M34: — | N34: 6 | O34: có
A35: Súng máy (LMG) | B35: DP-28 | C35: DP28 | D35: 105002 | E35: 7.62mm | H35: 6倍镜、4倍镜、3倍镜、2倍镜、全息瞄准镜、红点瞄准镜 | J35: — | K35: — | L35: — | M35: — | N35: 6 | O35: không
A36: Súng máy (LMG) | B36: MG3轻机枪 | C36: MG3 | D36: 105003 | E36: 7.62mm | H36: 红点、全息、2倍镜、3倍镜、4倍镜、6倍镜。 | J36: — | K36: — | L36: — | M36: — | N36: 6 | O36: không
A37: Súng ngắn | B37: P1911 | C37: (không có mã trong app) | D37: 106002 | E37: .45口径 | F37: 手枪消音器； | G37: 手枪扩容弹匣、手枪快速弹匣、手枪快速扩容弹匣； | H37: 全息瞄准镜、红点瞄准镜； | I37: 激光瞄准器 | J37: SUPPRESSOR | K37: LASER | L37: — | M37: — | N37: 1 | O37: không
A38: Súng ngắn | B38: P92 | C38: (không có mã trong app) | D38: 106001 | E38: 9mm | F38: 手枪消音器； | G38: 手枪扩容弹匣、手枪快速弹匣、手枪快速扩容弹匣； | H38: 全息瞄准镜、红点瞄准镜； | I38: 激光瞄准器 | J38: SUPPRESSOR | K38: LASER | L38: — | M38: — | N38: 1 | O38: không
A39: Súng ngắn | B39: R1895 | C39: (không có mã trong app) | D39: 106003 | E39: 7.62mm | F39: 手枪消音器 | J39: SUPPRESSOR | K39: — | L39: — | M39: — | N39: 0 | O39: không
A40: Súng ngắn | B40: P18C | C40: (không có mã trong app) | D40: 106004 | E40: 9mm | F40: 手枪消音器； | G40: 手枪扩容弹匣、手枪快速弹匣、手枪快速扩容弹匣； | H40: 全息瞄准镜、红点瞄准镜； | I40: 激光瞄准器 | J40: SUPPRESSOR | K40: LASER | L40: — | M40: — | N40: 1 | O40: không
A41: Súng ngắn | B41: R45 | C41: (không có mã trong app) | D41: 106005 | E41: .45口径 | H41: 全息瞄准镜、红点瞄准镜； | I41: 激光瞄准器 | J41: — | K41: LASER | L41: — | M41: — | N41: 1 | O41: không
...

Sheet Phụ kiện → súng (chính thức)
A1: Danh sách phụ kiện chính thức và các súng áp dụng được (Tencent, trường "súng áp dụng")
A2: Cột "Súng áp dụng" là nguyên văn danh sách của Tencent. Tay cầm Laser nằm trong nhóm tay cầm.
A4: Nhóm | B4: Phụ kiện | C4: ID | D4: Tác dụng | E4: Chỉ số | F4: Súng áp dụng (nguyên văn)
A5: 握把 | B5: 直角前握把（自动步枪，冲锋枪，狙击枪） | C5: 202001 | D5: 降低水平后坐力，同时提升瞄准速度。 | E5: -20.00% 后坐力效果; -20.00% 平行方向后坐力; +10.00% 快速瞄准 | F5: M416,SCAR-L,AUG,QBZ,M762,Mk47,G36C,SKS,UMP45
A6: 握把 | B6: 垂直握把（自动步枪，冲锋枪，狙击枪） | C6: 202002 | D6: 增加枪械稳定性，降低垂直后坐力。 | E6: -20.00% 后坐力效果; -15.00% 垂直方向后坐力 | F6: M416,SCAR-L,AUG,QBZ,M762,Mk47,G36C,SKS,UMP45,Vector,汤姆逊冲锋枪
A7: 握把 | B7: 拇指握把（步枪，冲锋枪，狙击枪） | C7: 202006 | D7: 提升瞄准速度，降低垂直后坐力，小幅提升枪械稳定性。 | E7: -5.00%垂直方向后坐力 -5.00%画面抖动 | F7: M416,SCAR-L,AUG,QBZ,M762,Mk47,G36C,SKS,UMP45
A8: 握把 | B8: 半截式握把（自动步枪，手枪，冲锋枪，狙击枪） | C8: 202005 | D8: 降低枪械后坐力，降低枪械稳定性。 | E8: -8.00%垂直方向后坐力 -10.00%水平方向后坐力 -15.00%画面抖动 | F8: M416,SCAR-L,AUG,QBZ,M762,Mk47,G36C,SKS,UMP45,Vector
A9: 握把 | B9: 轻型握把（自动步枪，手枪，冲锋枪，狙击枪） | C9: 202004 | D9: 增加枪械稳定性，降低后坐力。 | E9: -30.00%画面抖动 | F9: M416,SCAR-L,AUG,QBZ,M762,Mk47,G36C,SKS,UMP45,Vector
A10: 握把 | B10: 激光瞄准器（自动步枪，手枪，冲锋枪） | C10: 202007 | D10: 降低腰射时的子弹散布 | E10: 无 | F10: M416,SCAR-L,AUG,QBZ,M762,Mk47,G36C,SKS,UMP45,Vector,P92,P1911,P18C,蝎式手枪,R45
A11: 枪口 | B11: 霰弹枪收束器（霰弹枪，霰弹手枪） | C11: 201001 | D11: 降低霰弹枪子弹的扩散，使弹着点集中。 | E11: -18.20% 弹丸散射; +15.40% 弹丸速度 | F11: S1897,S686,短管霰弹枪
A12: 枪口 | B12: 枪口补偿器（冲锋枪） | C12: 201002 | D12: 增强枪械稳定性，降低水平及垂直后坐力。 | E12: -25.00% 后坐力效果； -20.00% 平行方向后坐力； -25.00% 垂直方向后坐力 | F12: UZI,UMP45,Vector,野牛冲锋枪
A13: 枪口 | B13: 枪口补偿器（狙击枪） | C13: 201003 | D13: 增强枪械稳定性，降低水平及垂直后坐力。 | E13: -25.00% 后坐力效果; -20.00% 平行方向后坐力; -20.00% 垂直方向后坐力 | F13: M24,AWM,SKS,Kar98K,Mk14,MiNi14,SLR,QBU
A14: 枪口 | B14: 消焰器（冲锋枪） | C14: 201004 | D14: 消除开火时枪口的火光，小幅降低水平及垂直后坐力。 | E14: -10.00% 后坐力效果; -10.00% 平行方向后坐力; -10.00% 垂直方向后坐力 | F14: UZI,UMP45,Vector,野牛冲锋枪
A15: 枪口 | B15: 消焰器（狙击枪） | C15: 201005 | D15: 消除开火时枪口的火光，小幅降低水平及垂直后坐力。 | E15: -10.00% 后坐力效果; -10.00% 平行方向后坐力; -10.00% 垂直方向后坐力 | F15: M24,AWM,SKS,Kar98K,Mk14,Mini14,SLR,QBU
... A21: 枪口 | B21: 消音器（自动步枪，S12K） | C21: 201011 | D21: 降低了武器开火时的声音，提升了隐蔽性。 | E21: -5.00% 后坐力效果 | F21: AKM,M16A4,M416,SCAR-L,S12K,SKS,GROZA,Mk14,Mini14,AUG,SLR,QBZ,QBU,M762,Mk47,G36C
A22: 枪口 | B22: 鸭嘴枪口 | C22: 201012 | D22: 降低枪械子弹的垂直散布，增加水平散布。 | F22: S1897,S12K
A23: 弹匣 | B23: 扩容弹匣（手枪） | C23: 204001 | D23: 增加了弹匣容量 | E23: 增加弹匣容量 | F23: P92,P1911,P18C,蝎式手枪
A24: 弹匣 | B24: 快速弹匣（手枪） | C24: 204002 | D24: 加快换弹速度 | E24: -30.00%装填时间 | F24: P92,P1911,P18C
A25: 弹匣 | B25: 快速扩容弹匣（手枪） | C25: 204003 | D25: 加快装弹速度提升弹匣容量 | E25: -30.00%装填时间; 增加弹匣容量 | F25: P92,P1911,P18C
A26: 弹匣 | B26: 扩容弹匣（冲锋枪） | C26: 204004 | D26: 增加了弹匣容量 | E26: 增加弹匣容量 | F26: UZI,UMP45,Vector,汤姆逊冲锋枪
A27: 弹匣 | B27: 快速弹匣（冲锋枪） | C27: 204005 | D27: 加快换弹速度 | E27: -30.00%装填时间 | F27: UZI,UMP45,Vector,汤姆逊冲锋枪
A28: 弹匣 | B28: 快速扩容弹匣（冲锋枪） | C28: 204006 | D28: 加快装弹速度提升弹夹容量 | E28: -30.00%装填时间; 增加弹匣容量 | F28: UZI,UMP45,Vector,汤姆逊冲锋枪
A29: 弹匣 | B29: 扩容弹匣（狙击枪） | C29: 204007 | D29: 增加了弹匣容量 | E29: 增加弹匣容量 | F29: M24,AWM,SKS,Mk14,Mini14,SLR,QBU,VSS
A30: 弹匣 | B30: 快速弹匣（狙击枪） | C30: 204008 | D30: 加快换弹速度 | E30: -30.00%装填时间 | F30: M24,AWM,SKS,VSS,Mk14,Mini14,QBU,SLR
A31: 弹匣 | B31: 快速扩容弹匣（狙击枪) | C31: 204009 | D31: 加快装弹速度提升弹夹容量 | E31: -30.00%装填时间; 增加弹匣容量 | F31: M24,AWM,SKS,VSS,Mk14,Mini14,SLR,QBU
A32: 弹匣 | B32: 子弹袋（霰弹枪） | C32: 204010 | D32: 加快换弹速度 | E32: -30.00%装填时间 | F32: S1897,S686
A33: 弹匣 | B33: 扩容弹匣（自动步枪，S12K） | C33: 204011 | D33: 增加了弹匣容量 | E33: 增加弹匣容量 | F33: AKM,M16A4,M416,SCAR-L,AUG,GROZA,S12K,QBZ,M762,Mk47,G36C,SKS,Mk14,Mini14,VSS,SLR,QBU
A34: 弹匣 | B34: 快速弹匣（自动步枪，S12K） | C34: 204012 | D34: 加快换弹速度 | E34: -30.00%装填时间 | F34: AKM,M16A4,M416,SCAR-L,AUG,GROZA,S12K,QBZ,M762,Mk47,G36C,SKS,Mk14,Mini14,VSS,SLR,QBU
... A48: 瞄准镜 | B48: 侧瞄准镜 | C48: 203007 | D48: 方便在中远距离点射和近距离扫射间快速切换。 | E48: 侧面瞄准 | F48: M416,AKM,SCAR-L,AUG,QBZ,M762,MK47,G36C,Kar98K,M24,AWM,SKS,Mini14,Mk14,SLR,QBU,UMP45,Vector,野牛冲锋枪,S12K,M249

Sheet AppMedia (toàn cầu 2022)
A1: AppMedia: bảng phụ kiện PUBG Mobile bản toàn cầu (cập nhật 27/05/2022, đã ngừng cập nhật)
A2: Nguồn: https://appmedia.jp/pubg/1847028 . Chép lại từ bản đọc của trang; chính trang cảnh báo văn bản có thể lẫn. Viết tắt: RD=Red Dot, Holo, Comp=Hãm giật, FH=Ẩn tia lửa, Supp=Giảm thanh, VG=Đứng, AG=Tam giác, TG=Ngón cái, HG=Half, LG=Nhẹ, TS=Báng chiến thuật, CP=Ốp má, SH=Vỏ đạn.
A4: Loại | B4: Súng | C4: Ống ngắm | D4: Đầu nòng | E4: Tay cầm | F4: Băng đạn | G4: Báng | H4: Khác
A5: HG | B5: Deagle | C5: RD, Holo | D5: — | E5: — | F5: QD, LM, LQD | G5: — | H5: Laser
A6: HG | B6: P1911 | C6: RD, Holo | D6: Supp | E6: — | F6: QD, LM, LQD | G6: — | H6: Laser
A7: HG | B7: R45 | C7: RD, Holo | D7: — | E7: — | F7: — | G7: — | H7: Laser
A8: HG | B8: R1895 | C8: — | D8: Supp | E8: — | F8: — | G8: — | H8: —
A9: HG | B9: P18C | C9: RD, Holo | D9: Supp | E9: — | F9: QD, LM, LQD | G9: — | H9: Laser
A10: HG | B10: P92 | C10: RD, Holo | D10: Supp | E10: — | F10: QD, LM, LQD | G10: — | H10: Laser
A11: HG | B11: Skorpion | C11: RD, Holo | D11: Supp | E11: VG, LG, HG | F11: LM | G11: Stock | H11: Laser
A12: HG | B12: Sawed-off | C12: — | D12: — | E12: — | F12: — | G12: — | H12: Choke
A13: SG | B13: M1014 | C13: — | D13: — | E13: — | F13: — | G13: — | H13: Choke, Duckbill, SH
A14: SG | B14: S12K | C14: RD, Holo, Canted, 2–6x | D14: — | E14: — | F14: — | G14: — | H14: —
A15: SG | B15: S1897 | C15: — | D15: — | E15: — | F15: — | G15: — | H15: Choke, Duckbill, SH
... A51: Cung | B51: Crossbow | C51: RD, Holo, 2–6x | D51: — | E51: — | F51: — | G51: — | H51: Quiver

Sheet Nguồn
A1: Nguồn đã dùng và mức độ tin cậy
A3: # | B3: Nguồn | C3: URL | D3: Ngày / phiên bản | E3: Loại | F3: Dùng cho | G3: Đánh giá | H3: Hạn chế
A4: 1 | B4: Tencent: kho vũ khí 和平精英 (dữ liệu JSON) | C4: https://gp.qq.com/zlkdatasys/data_zlk_hpjywqzlk1.json (trang: https://gp.qq.com/cp/a20251120arsenal/index.html) | D4: Trang tạo 20/11/2025 (theo đường dẫn); dữ liệu 45 vũ khí | E4: Chính thức | F4: 33 súng khớp mã của app + toàn bộ danh sách phụ kiện → súng | G4: Cao nhất cho bản 和平精英 | H4: Chỉ 45 vũ khí (không có Mosin, MP5K, P90, M1014, AMR, M417, ACE32, FAMAS, MK12...). Trang ghi dữ liệu do người chơi thu thập, lấy thông số trong game làm chuẩn.
A5: 2 | B5: AppMedia: 武器一覧 (bảng phụ kiện PUBG Mobile toàn cầu) | C5: https://appmedia.jp/pubg/1847028 | D5: 27/05/2022, đã ngừng cập nhật | E5: Cộng đồng (Nhật), bản toàn cầu | F5: Mosin, M1014, MP5K, P90; kiểm chứng chéo CrossBow, MG3, M249, DBS, Bizon, Win94, FAMAS, MK12 | G5: Trung bình | H5: Bản toàn cầu, không phải 和平精英; cũ (2022); văn bản đọc ra có thể lẫn hàng.
A6: 3 | B6: AppMedia: DP-28 | C6: https://appmedia.jp/?p=1864707 | D6: 05/08/2022 | E6: Cộng đồng (Nhật) | F6: Kiểm chứng DP-28 (chỉ ống ngắm đến 6x) | G6: Trung bình | H6: Cũ; khớp dữ liệu chính thức.
A7: 4 | B7: mobilematters.gg: Best AMR loadout | C7: https://mobilematters.gg/pubg/best-amr-loadout-in-pubg-mobile | D7: Không ghi ngày (chân trang 2026) | E7: Blog hướng dẫn | F7: AMR: chỉ một khe (ống ngắm), khuyên 8x | G7: Trung bình-thấp | H7: Một nguồn; không phải chính thức.
A8: 5 | B8: mobilematters.gg: loadout MP5K, P90, M249 | C8: https://mobilematters.gg/pubg/best-mp5k-loadout-pubg-mobile ; /pubg/best-m249-loadout-pubg-mobile-complete-attachment-setup ; /guides/best-p90-loadout-pubg-mobile | D8: Khoảng 600 ngày trước (theo kết quả tìm kiếm) | E8: Blog hướng dẫn | F8: Kiểm chứng chéo MP5K (tay cầm tam giác), P90 (Laser), M249 (báng chiến thuật) | G8: Thấp-trung bình | H8: Mô tả cấu hình khuyên dùng, không phải danh sách đầy đủ; chỉ qua tóm tắt tìm kiếm.
A9: 6 | B9: game.xiaomi.com: đánh giá AMR trong 和平精英 | C9: https://game.xiaomi.com/viewpoint/1012323863_1636530131682_13 | D9: Cũ (2021) | E9: Cộng đồng | F9: AMR "chỉ cần một ống ngắm là đủ" | G9: Thấp-trung bình | H9: Chỉ qua tóm tắt tìm kiếm.
A10: 7 | B10: gurugamer.com: M417 sắp ra mắt | C10: https://gurugamer.com/mobile-games/new-gun-m417-to-arrive-in-pubg-mobile-bgmi-20281/amp | D10: Trước khi phát hành (2022) | E10: Blog tin tức | F10: M417: ống ngắm đến 8x, băng đạn mặc định 10 viên | G10: Thấp | H10: Bài trước phát hành; không nêu nòng/tay cầm/báng.
A11: 8 | B11: Dexerto wiki: JS9 (PUBG PC) | C11: https://www.dexerto.com/wikis/pubg/weapons/submachine-gun/js9/ | D11: Không rõ | E11: Wiki PUBG PC | F11: JS9: nòng SMG (chỉ để tham khảo) | G11: Thấp | H11: Là PUBG PC, không phải PUBG Mobile/和平精英. KHÔNG dùng để đặt quy tắc.
A12: 9 | B12: IMFDB: Talk:PUBG Battlegrounds | C12: https://imfdb.org/wiki/Talk:PUBG:_Battlegrounds | D12: Không rõ | E12: Wiki súng trong phim/game | F12: Nhận diện tên: ASM = ASM Abakan, Mk20-H = FN SSR, M1 = M1 Garand, M338 = SIG MG 338, MP7 | G12: Thấp | H12: Chỉ để đoán tên súng, không có dữ liệu phụ kiện.
A13: 10 | B13: Tencent: bài "Cách chọn phụ kiện" (2019) và bài về báng (2019) | C13: https://gp.qq.com/gicp/news/736/8836332.html ; https://gp.qq.com/gicp/news/684/7850544.html | D13: 28/11/2019 và 24/08/2019 | E13: Chính thức (cũ) | F13: Báng: UZI và Skorpion dùng báng thường; M416, Vector (và Mk47) dùng báng chiến thuật | G13: Trung bình | H13: Cũ; trang gặp lỗi mã hóa nên chỉ đọc được từng đoạn.
A14: 11 | B14: Các nguồn đã thử nhưng không dùng được | C14: pubgmobile.fandom.com (HTTP 402), breezewiki (chặn bot), baike.baidu.com (403), pubg.wiki.gg và Dexerto (PUBG PC) | D14: — | E14: — | F14: — | G14: — | H14: Không đọc được hoặc không phải bản mobile.

Sheet Ghi chú và giả định
A1: Ghi chú, giả định và cách đọc
A3: # | B3: Nội dung
A4: 1 | B4: Phiên bản game: tên bộ cấu hình của bạn là "和平精英" (Game for Peace, bản Trung Quốc của PUBG Mobile). Dữ liệu chính thức dùng ở đây là của bản này. Các nguồn bản toàn cầu (AppMedia, mobilematters) có thể khác (ví dụ M249: bản toàn cầu có báng chiến thuật).
A5: 2 | B5: Không có ống ngắm 16x: dữ liệu chính thức 和平精英 cao nhất là 8x (súng bắn tỉa, xạ thủ), 6x (AR, SMG, shotgun, súng máy, nỏ). Các giá trị 15x ghi trước đây trong app đã được bạn sửa về 8x; trong app mục ống ngắm cao nhất cũng là 8x (X8, X84, tactic, tactic_84).
A6: 3 | B6: Ánh xạ tên tay cầm: Angled/tam giác = HORIZONTAL; Vertical = VERTICAL; Thumb = THUMB; Light = LIGHT; Half = HALF; "激光瞄准器" (Laser) = LASER (Tencent xếp Laser vào nhóm tay cầm). ERGONOMIC (công thái học) KHÔNG có trong dữ liệu chính thức.
A7: 4 | B7: Ánh xạ nòng: Compensator = COMPENSATOR; Flash Hider = FLASH_HIDER; Suppressor = SUPPRESSOR. BRAKE, EXTENDER, BRAKE_NEW của app không có trong dữ liệu chính thức. Choke (霰弹收束器) và Duckbill (鸭嘴枪口) của shotgun không có chỗ trong danh sách nòng của app.
A8: 5 | B8: Ánh xạ báng: "战术枪托" (báng chiến thuật) và "枪托" (báng thường của UZI, Skorpion) đều được ghi là GENERAL (app chỉ có GENERAL và GENERAL_NEW; chưa biết app dùng GENERAL cho loại nào). Ốp má (托腮板), Túi đạn (子弹袋), Túi tên (箭袋) không có trong danh sách báng/tay cầm của app nên coi là "không có".
A9: 6 | B9: Băng đạn không được app mô hình hóa nên không nằm trong quy tắc.
A10: 7 | B10: Mức tin cậy: Cao = dữ liệu chính thức 和平精英 (kiểm chứng chéo nếu có); Trung bình = nguồn thứ cấp bản toàn cầu hoặc có mâu thuẫn; Thấp = bài trước phát hành, bản PC hoặc suy luận; Chưa tìm thấy = không có nguồn đáng tin; Không áp dụng = không phải súng.
A11: 8 | B11: Tên súng được "nhận diện" từ mã trong app. Nhiều mã (HB, MG97, ChiXiao, ACVAL...) chưa nhận diện được: đừng coi tên trong cột C của các dòng đó là chắc chắn.
A12: 9 | B12: Súng "không đủ dữ liệu" được để TRỐNG ở cột đề xuất: app sẽ không hạn chế gì cho súng đó, thay vì đoán sai.
A13: 10 | B13: Chưa có gì trong file này được áp dụng vào app. Đây là đề xuất để bạn duyệt.
A14: 11 | B14: Nội dung tìm kiếm trên mạng đa phần đến từ tóm tắt công cụ tìm kiếm; các nguồn đã đọc trực tiếp đầy đủ là dữ liệu JSON chính thức của Tencent và trang AppMedia.
